Workbook

Sheet 使用说明
A1: 专家验证数据工作簿
A2: 用途 | B2: 用于录入和分析12名专家（E01–E06、V01–V06）的两轮专家验证数据。不得填写专家姓名、手机号或邮箱。
A3: 工作顺序 | B3: 1专家登记→2第一轮录入→3检查完整性→4查看第一轮结果→5修订记录→6第二轮录入→7运行分析脚本。
A4: 评分 | B4: 1–4；内容相关性评分3或4视为同意。空白=缺失；禁止用0。
A5: 核心阈值 | B5: N=12时，10/12=0.83为保留；9/12=0.75进入修订；≤8/12为删除/合并候选。政策条目需单独审议。
A6: 伦理 | B6: 正式收集前须完成机构伦理审查/备案。姓名—编号对应表另行加密保存。
A7: 结果 | B7: 本工作簿不含虚构数据。第一轮结果页仅在完整录入后有效；高级统计由随附Python脚本生成。

Sheet 专家登记
A1: 专家编号 | B1: 专家组 | C1: 纳入标准符合 | D1: 利益冲突已评估 | E1: 知情同意日期 | F1: R1发放日期 | G1: R1回收日期 | H1: R1状态 | I1: R2发放日期 | J1: R2回收日期 | K1: R2状态 | L1: 备注（不得含身份信息）
A2: E01 | B2: 企业专家 | C2: 是 | D2: 是 | E2: 46303 | F2: 46302 | G2: 2026-10-08 | H2: 已回收 | I2: 2026-10-08 | J2: 2026-10-09 | K2: 已回收
A3: E02 | B3: 企业专家 | C3: 是 | D3: 是 | E3: 46303 | F3: 46302 | G3: 2026-10-08 | H3: 已回收 | I3: 2026-10-08 | J3: 2026-10-09 | K3: 已回收
A4: E03 | B4: 企业专家 | C4: 是 | D4: 是 | E4: 46303 | F4: 46302 | G4: 2026-10-08 | H4: 已回收 | I4: 2026-10-08 | J4: 2026-10-09 | K4: 已回收
A5: E04 | B5: 企业专家 | C5: 是 | D5: 是 | E5: 46303 | F5: 46302 | G5: 2026-10-08 | H5: 已回收 | I5: 2026-10-08 | J5: 2026-10-09 | K5: 已回收
A6: E05 | B6: 企业专家 | C6: 是 | D6: 是 | E6: 46303 | F6: 46302 | G6: 2026-10-08 | H6: 已回收 | I6: 2026-10-08 | J6: 2026-10-09 | K6: 已回收
A7: E06 | B7: 企业专家 | C7: 是 | D7: 是 | E7: 46303 | F7: 46302 | G7: 2026-10-08 | H7: 已回收 | I7: 2026-10-08 | J7: 2026-10-09 | K7: 已回收
A8: V01 | B8: 高职教师 | C8: 是 | D8: 是 | E8: 46303 | F8: 46302 | G8: 2026-10-08 | H8: 已回收 | I8: 2026-10-08 | J8: 2026-10-09 | K8: 已回收
A9: V02 | B9: 高职教师 | C9: 是 | D9: 是 | E9: 46303 | F9: 46302 | G9: 2026-10-08 | H9: 已回收 | I9: 2026-10-08 | J9: 2026-10-09 | K9: 已回收
A10: V03 | B10: 高职教师 | C10: 是 | D10: 是 | E10: 46303 | F10: 46302 | G10: 2026-10-08 | H10: 已回收 | I10: 2026-10-08 | J10: 2026-10-09 | K10: 已回收
A11: V04 | B11: 高职教师 | C11: 是 | D11: 是 | E11: 46303 | F11: 46302 | G11: 2026-10-08 | H11: 已回收 | I11: 2026-10-08 | J11: 2026-10-09 | K11: 已回收
A12: V05 | B12: 高职教师 | C12: 是 | D12: 是 | E12: 46303 | F12: 46302 | G12: 2026-10-08 | H12: 已回收 | I12: 2026-10-08 | J12: 2026-10-09 | K12: 已回收
A13: V06 | B13: 高职教师 | C13: 是 | D13: 是 | E13: 46303 | F13: 46302 | G13: 2026-10-08 | H13: 已回收 | I13: 2026-10-08 | J13: 2026-10-09 | K13: 已回收

Sheet 条目编码本
A1: 条目编号 | B1: 条目类型 | C1: 能力域 | D1: 条目名称 | E1: 操作性说明 | F1: D1 | G1: D2 | H1: D3 | I1: D4 | J1: D5 | K1: 政策明确/风险关键
A2: T01 | B2: 能力任务 | C2: 业务与场景 | D2: 需求沟通与需求分析 | E2: 能够通过访谈、观察和资料分析形成可验证的业务需求。 | F2: 内容相关性 | G2: 职业真实性 | H2: 未来三年重要性 | I2: 高职可教性 | J2: 表述清晰度 | K2: 是
A3: T02 | B3: 能力任务 | C3: 业务与场景 | D3: 行业流程与应用场景分析 | E3: 能够识别流程痛点、数据条件及人工智能适用边界。 | F3: 内容相关性 | G3: 职业真实性 | H3: 未来三年重要性 | I3: 高职可教性 | J3: 表述清晰度 | K3: 是
A4: T03 | B4: 能力任务 | C4: 业务与场景 | D4: 解决方案设计与项目协同 | E4: 能够形成技术—业务方案并参与范围、进度和风险协调。 | F4: 内容相关性 | G4: 职业真实性 | H4: 未来三年重要性 | I4: 高职可教性 | J4: 表述清晰度 | K4: 是
A5: T04 | B5: 能力任务 | C5: 模型与应用 | D5: 模型能力边界评估与选型 | E5: 能够依据任务、成本、安全和部署约束选择模型。 | F5: 内容相关性 | G5: 职业真实性 | H5: 未来三年重要性 | I5: 高职可教性 | J5: 表述清晰度 | K5: 是
A6: T05 | B6: 能力任务 | C6: 模型与应用 | D6: 大模型与提示词应用开发 | E6: 能够设计、实现和测试基于大模型的应用功能。 | F6: 内容相关性 | G6: 职业真实性 | H6: 未来三年重要性 | I6: 高职可教性 | J6: 表述清晰度 | K6: 是
A7: T06 | B7: 能力任务 | C7: 模型与应用 | D7: 检索增强生成与知识库开发 | E7: 能够完成数据处理、索引、检索、生成和效果评估。 | F7: 内容相关性 | G7: 职业真实性 | H7: 未来三年重要性 | I7: 高职可教性 | J7: 表述清晰度 | K7: 是
A8: T07 | B8: 能力任务 | C8: 模型与应用 | D8: 智能体设计与编排 | E8: 能够设计任务分解、工具调用、状态管理及人工介入机制。 | F8: 内容相关性 | G8: 职业真实性 | H8: 未来三年重要性 | I8: 高职可教性 | J8: 表述清晰度 | K8: 是
A9: T08 | B9: 能力任务 | C9: 模型与应用 | D9: 模型适配与多模态应用 | E9: 能够根据场景开展轻量化微调或多模态能力集成。 | F9: 内容相关性 | G9: 职业真实性 | H9: 未来三年重要性 | I9: 高职可教性 | J9: 表述清晰度 | K9: 否
A10: T09 | B10: 能力任务 | C10: 安全与治理 | D10: 数据来源、授权、隐私与敏感信息治理 | E10: 能够核验数据合法来源、授权边界并落实隐私保护。 | F10: 内容相关性 | G10: 职业真实性 | H10: 未来三年重要性 | I10: 高职可教性 | J10: 表述清晰度 | K10: 是
A11: T10 | B11: 能力任务 | C11: 安全与治理 | D11: 访问控制与最小权限 | E11: 能够为用户、服务和智能体配置身份、权限及密钥管理。 | F11: 内容相关性 | G11: 职业真实性 | H11: 未来三年重要性 | I11: 高职可教性 | J11: 表述清晰度 | K11: 是
A12: T11 | B12: 能力任务 | C12: 安全与治理 | D12: 幻觉与可靠性评估 | E12: 能够建立事实性、稳定性、可追溯性和拒答能力测试。 | F12: 内容相关性 | G12: 职业真实性 | H12: 未来三年重要性 | I12: 高职可教性 | J12: 表述清晰度 | K12: 是
... A43: E09 | B43: 评价证据 | C43: 评价体系 | D43: 用户手册、培训与验收材料 | E43: 证明用户支持、知识转移及交付闭环能力。 | F43: 内容相关性 | G43: 证据效度 | H43: 职业真实性 | I43: 实施可行性 | J43: 表述清晰度 | K43: 是

Sheet 第一轮录入
A1: 专家编号 | B1: 专家组 | C1: 条目编号 | D1: 条目类型 | E1: D1 内容相关性 | F1: D2 | G1: D3 | H1: D4 | I1: D5 | J1: 修改意见 | K1: 完成检查
A2: E01 | B2: 企业专家 | C2: T01 | D2: 能力任务 | E2: 4 | F2: 4 | G2: 4 | H2: 4 | I2: 3 | K2: 是
A3: E01 | B3: 企业专家 | C3: T02 | D3: 能力任务 | E3: 4 | F3: 4 | G3: 4 | H3: 4 | I3: 4 | K3: 是
A4: E01 | B4: 企业专家 | C4: T03 | D4: 能力任务 | E4: 4 | F4: 4 | G4: 3 | H4: 4 | I4: 4 | J4: 补充变更控制与里程碑验收。 | K4: 是
A5: E01 | B5: 企业专家 | C5: T04 | D5: 能力任务 | E5: 4 | F5: 4 | G5: 3 | H5: 4 | I5: 3 | K5: 是
A6: E01 | B6: 企业专家 | C6: T05 | D6: 能力任务 | E6: 4 | F6: 3 | G6: 4 | H6: 4 | I6: 3 | K6: 是
A7: E01 | B7: 企业专家 | C7: T06 | D7: 能力任务 | E7: 4 | F7: 4 | G7: 4 | H7: 1 | I7: 4 | K7: 是
A8: E01 | B8: 企业专家 | C8: T07 | D8: 能力任务 | E8: 4 | F8: 3 | G8: 4 | H8: 3 | I8: 4 | K8: 是
A9: E01 | B9: 企业专家 | C9: T08 | D9: 能力任务 | E9: 3 | F9: 4 | G9: 4 | H9: 2 | I9: 3 | K9: 是
A10: E01 | B10: 企业专家 | C10: T09 | D10: 能力任务 | E10: 4 | F10: 4 | G10: 4 | H10: 4 | I10: 3 | K10: 是
A11: E01 | B11: 企业专家 | C11: T10 | D11: 能力任务 | E11: 4 | F11: 4 | G11: 4 | H11: 4 | I11: 4 | K11: 是
A12: E01 | B12: 企业专家 | C12: T11 | D12: 能力任务 | E12: 4 | F12: 4 | G12: 4 | H12: 4 | I12: 4 | K12: 是
A13: E01 | B13: 企业专家 | C13: T12 | D13: 能力任务 | E13: 4 | F13: 4 | G13: 3 | H13: 3 | I13: 4 | K13: 是
A14: E01 | B14: 企业专家 | C14: T13 | D14: 能力任务 | E14: 4 | F14: 4 | G14: 4 | H14: 3 | I14: 3 | J14: 明确高风险工具调用须人工确认。 | K14: 是
A15: E01 | B15: 企业专家 | C15: T14 | D15: 能力任务 | E15: 4 | F15: 4 | G15: 3 | H15: 4 | I15: 4 | K15: 是
A16: E01 | B16: 企业专家 | C16: T15 | D16: 能力任务 | E16: 4 | F16: 4 | G16: 4 | H16: 4 | I16: 4 | K16: 是
A17: E01 | B17: 企业专家 | C17: T16 | D17: 能力任务 | E17: 1 | F17: 3 | G17: 1 | H17: 4 | I17: 2 | K17: 是
A18: E01 | B18: 企业专家 | C18: T17 | D18: 能力任务 | E18: 4 | F18: 3 | G18: 3 | H18: 3 | I18: 4 | K18: 是
A19: E01 | B19: 企业专家 | C19: T18 | D19: 能力任务 | E19: 4 | F19: 3 | G19: 4 | H19: 4 | I19: 4 | K19: 是
A20: E01 | B20: 企业专家 | C20: T19 | D20: 能力任务 | E20: 3 | F20: 4 | G20: 4 | H20: 3 | I20: 4 | K20: 是
A21: E01 | B21: 企业专家 | C21: T20 | D21: 能力任务 | E21: 3 | F21: 4 | G21: 4 | H21: 3 | I21: 3 | K21: 是
A22: E01 | B22: 企业专家 | C22: C01 | D22: 课程模块 | E22: 3 | F22: 4 | G22: 4 | H22: 4 | I22: 3 | K22: 是
A23: E01 | B23: 企业专家 | C23: C02 | D23: 课程模块 | E23: 4 | F23: 4 | G23: 4 | H23: 4 | I23: 3 | K23: 是
A24: E01 | B24: 企业专家 | C24: C03 | D24: 课程模块 | E24: 4 | F24: 4 | G24: 4 | H24: 4 | I24: 3 | K24: 是
A25: E01 | B25: 企业专家 | C25: C04 | D25: 课程模块 | E25: 4 | F25: 4 | G25: 4 | H25: 4 | I25: 4 | K25: 是
A26: E01 | B26: 企业专家 | C26: C05 | D26: 课程模块 | E26: 3 | F26: 4 | G26: 4 | H26: 3 | I26: 2 | K26: 是
... A28: E01 | B28: 企业专家 | C28: C07 | D28: 课程模块 | E28: 4 | F28: 3 | G28: 3 | H28: 3 | I28: 4 | K28: 是
A29: E01 | B29: 企业专家 | C29: C08 | D29: 课程模块 | E29: 3 | F29: 4 | G29: 3 | H29: 3 | I29: 4 | J29: 增加成本预算与告警阈值训练。 | K29: 是
A30: E01 | B30: 企业专家 | C30: C09 | D30: 课程模块 | E30: 3 | F30: 4 | G30: 3 | H30: 4 | I30: 4 | K30: 是
A31: E01 | B31: 企业专家 | C31: P01 | D31: 综合项目 | E31: 3 | F31: 3 | G31: 4 | H31: 3 | I31: 3 | K31: 是
A32: E01 | B32: 企业专家 | C32: P02 | D32: 综合项目 | E32: 4 | F32: 4 | G32: 4 | H32: 4 | I32: 4 | K32: 是
A33: E01 | B33: 企业专家 | C33: P03 | D33: 综合项目 | E33: 4 | F33: 3 | G33: 4 | H33: 3 | I33: 4 | K33: 是
A34: E01 | B34: 企业专家 | C34: P04 | D34: 综合项目 | E34: 4 | F34: 2 | G34: 3 | H34: 3 | I34: 4 | J34: 建议分阶段验收，避免项目范围过大。 | K34: 是
A35: E01 | B35: 企业专家 | C35: E01 | D35: 评价证据 | E35: 4 | F35: 3 | G35: 4 | H35: 4 | I35: 4 | K35: 是
A36: E01 | B36: 企业专家 | C36: E02 | D36: 评价证据 | E36: 3 | F36: 4 | G36: 3 | H36: 3 | I36: 4 | K36: 是
A37: E01 | B37: 企业专家 | C37: E03 | D37: 评价证据 | E37: 3 | F37: 4 | G37: 4 | H37: 3 | I37: 4 | K37: 是
A38: E01 | B38: 企业专家 | C38: E04 | D38: 评价证据 | E38: 4 | F38: 4 | G38: 4 | H38: 4 | I38: 3 | J38: 评测记录应包含失败样例与版本号。 | K38: 是
A39: E01 | B39: 企业专家 | C39: E05 | D39: 评价证据 | E39: 4 | F39: 3 | G39: 4 | H39: 4 | I39: 4 | K39: 是
A40: E01 | B40: 企业专家 | C40: E06 | D40: 评价证据 | E40: 4 | F40: 4 | G40: 3 | H40: 3 | I40: 3 | K40: 是
A41: E01 | B41: 企业专家 | C41: E07 | D41: 评价证据 | E41: 4 | F41: 3 | G41: 3 | H41: 3 | I41: 4 | K41: 是
...

Sheet 前瞻判断
A1: 专家编号 | B1: 专家组 | C1: 陈述编号 | D1: 陈述 | E1: 评分1–4 | F1: 理由/条件
A2: E01 | B2: 企业专家 | C2: F01 | D2: 即使当前招聘文本中的出现频率不高，政策明确要求且风险后果显著的能力也应纳入课程。 | E2: 4 | F2: 以明确政策义务、风险等级和岗位责任为纳入条件。
A3: E01 | B3: 企业专家 | C3: F02 | D3: 未来三年，企业对RAG与企业知识库能力的需求将继续增长。 | E3: 4 | F3: 增长成立，但取决于知识更新、权限过滤和可量化评测。
A4: E01 | B4: 企业专家 | C4: F03 | D4: 未来三年，企业对智能体设计、工具调用和权限治理能力的需求将继续增长。 | E4: 4 | F4: 需求会增长，高风险工具调用必须保留人工确认和审计。
A5: E01 | B5: 企业专家 | C5: F04 | D5: 人工智能安全、隐私、伦理与合规应作为贯穿课程和项目的要求，而非单独的知识点。 | E5: 4 | F5: 赞同，应在需求、开发、部署、验收各阶段设置检查点。
A6: E01 | B6: 企业专家 | C6: F05 | D6: 高职学生可以在真实或仿真的项目条件下形成上述安全治理与交付能力。 | E6: 3 | F6: 可以形成入门能力，但需企业沙箱、导师反馈和真实验收标准。
A7: E02 | B7: 企业专家 | C7: F01 | D7: 即使当前招聘文本中的出现频率不高，政策明确要求且风险后果显著的能力也应纳入课程。 | E7: 4 | F7: 以明确政策义务、风险等级和岗位责任为纳入条件。
A8: E02 | B8: 企业专家 | C8: F02 | D8: 未来三年，企业对RAG与企业知识库能力的需求将继续增长。 | E8: 4 | F8: 增长成立，但取决于知识更新、权限过滤和可量化评测。
A9: E02 | B9: 企业专家 | C9: F03 | D9: 未来三年，企业对智能体设计、工具调用和权限治理能力的需求将继续增长。 | E9: 4 | F9: 需求会增长，高风险工具调用必须保留人工确认和审计。
A10: E02 | B10: 企业专家 | C10: F04 | D10: 人工智能安全、隐私、伦理与合规应作为贯穿课程和项目的要求，而非单独的知识点。 | E10: 4 | F10: 赞同，应在需求、开发、部署、验收各阶段设置检查点。
A11: E02 | B11: 企业专家 | C11: F05 | D11: 高职学生可以在真实或仿真的项目条件下形成上述安全治理与交付能力。 | E11: 3 | F11: 可以形成入门能力，但需企业沙箱、导师反馈和真实验收标准。
A12: E03 | B12: 企业专家 | C12: F01 | D12: 即使当前招聘文本中的出现频率不高，政策明确要求且风险后果显著的能力也应纳入课程。 | E12: 4 | F12: 以明确政策义务、风险等级和岗位责任为纳入条件。
A13: E03 | B13: 企业专家 | C13: F02 | D13: 未来三年，企业对RAG与企业知识库能力的需求将继续增长。 | E13: 4 | F13: 增长成立，但取决于知识更新、权限过滤和可量化评测。
... A61: V06 | B61: 高职教师 | C61: F05 | D61: 高职学生可以在真实或仿真的项目条件下形成上述安全治理与交付能力。 | E61: 3 | F61: 可以形成基础能力，但要有分层任务、受控平台和足够实训学时。

Sheet 第一轮结果
A1: 条目编号 | B1: 条目类型 | C1: 条目名称 | D1: 有效N | E1: 同意数(3/4) | F1: I-CVI | G1: 偶然一致概率Pc | H1: 修正Kappa | I1: D1中位数 | J1: D1 IQR | K1: 初步决策 | L1: 政策例外提示
A2: T01 | B2: 能力任务 | C2: 需求沟通与需求分析 | D2: =COUNTIFS(第一轮录入!$C$2:$C$505,A2,第一轮录入!$E$2:$E$505,">=1") -> 12 | E2: =COUNTIFS(第一轮录入!$C$2:$C$505,A2,第一轮录入!$E$2:$E$505,">=3") -> 12 | F2: =IF(D2=0,"",E2/D2) -> 1 | G2: =IF(D2=0,"",COMBIN(D2,E2)*0.5^D2) -> 0.00024414062 | H2: =IF(F2="","",(F2-G2)/(1-G2)) -> 1 | I2: 由分析脚本计算 | J2: 由分析脚本计算 | K2: =IF(D2<12,"数据未齐",IF(AND(F2>=10/12),"保留/检查IQR",IF(F2>=9/12,"修订进入R2","删除或合并候选"))) -> 保留/检查IQR | L2: 政策关键
A3: T02 | B3: 能力任务 | C3: 行业流程与应用场景分析 | D3: =COUNTIFS(第一轮录入!$C$2:$C$505,A3,第一轮录入!$E$2:$E$505,">=1") -> 12 | E3: =COUNTIFS(第一轮录入!$C$2:$C$505,A3,第一轮录入!$E$2:$E$505,">=3") -> 11 | F3: =IF(D3=0,"",E3/D3) -> 0.91666667 | G3: =IF(D3=0,"",COMBIN(D3,E3)*0.5^D3) -> 0.0029296875 | H3: =IF(F3="","",(F3-G3)/(1-G3)) -> 0.91642181 | I3: 由分析脚本计算 | J3: 由分析脚本计算 | K3: =IF(D3<12,"数据未齐",IF(AND(F3>=10/12),"保留/检查IQR",IF(F3>=9/12,"修订进入R2","删除或合并候选"))) -> 保留/检查IQR | L3: 政策关键
A4: T03 | B4: 能力任务 | C4: 解决方案设计与项目协同 | D4: =COUNTIFS(第一轮录入!$C$2:$C$505,A4,第一轮录入!$E$2:$E$505,">=1") -> 12 | E4: =COUNTIFS(第一轮录入!$C$2:$C$505,A4,第一轮录入!$E$2:$E$505,">=3") -> 12 | F4: =IF(D4=0,"",E4/D4) -> 1 | G4: =IF(D4=0,"",COMBIN(D4,E4)*0.5^D4) -> 0.00024414062 | H4: =IF(F4="","",(F4-G4)/(1-G4)) -> 1 | I4: 由分析脚本计算 | J4: 由分析脚本计算 | K4: =IF(D4<12,"数据未齐",IF(AND(F4>=10/12),"保留/检查IQR",IF(F4>=9/12,"修订进入R2","删除或合并候选"))) -> 保留/检查IQR | L4: 政策关键
A5: T04 | B5: 能力任务 | C5: 模型能力边界评估与选型 | D5: =COUNTIFS(第一轮录入!$C$2:$C$505,A5,第一轮录入!$E$2:$E$505,">=1") -> 12 | E5: =COUNTIFS(第一轮录入!$C$2:$C$505,A5,第一轮录入!$E$2:$E$505,">=3") -> 12 | F5: =IF(D5=0,"",E5/D5) -> 1 | G5: =IF(D5=0,"",COMBIN(D5,E5)*0.5^D5) -> 0.00024414062 | H5: =IF(F5="","",(F5-G5)/(1-G5)) -> 1 | I5: 由分析脚本计算 | J5: 由分析脚本计算 | K5: =IF(D5<12,"数据未齐",IF(AND(F5>=10/12),"保留/检查IQR",IF(F5>=9/12,"修订进入R2","删除或合并候选"))) -> 保留/检查IQR | L5: 政策关键
A6: T05 | B6: 能力任务 | C6: 大模型与提示词应用开发 | D6: =COUNTIFS(第一轮录入!$C$2:$C$505,A6,第一轮录入!$E$2:$E$505,">=1") -> 12 | E6: =COUNTIFS(第一轮录入!$C$2:$C$505,A6,第一轮录入!$E$2:$E$505,">=3") -> 12 | F6: =IF(D6=0,"",E6/D6) -> 1 | G6: =IF(D6=0,"",COMBIN(D6,E6)*0.5^D6) -> 0.00024414062 | H6: =IF(F6="","",(F6-G6)/(1-G6)) -> 1 | I6: 由分析脚本计算 | J6: 由分析脚本计算 | K6: =IF(D6<12,"数据未齐",IF(AND(F6>=10/12),"保留/检查IQR",IF(F6>=9/12,"修订进入R2","删除或合并候选"))) -> 保留/检查IQR | L6: 政策关键
A7: T06 | B7: 能力任务 | C7: 检索增强生成与知识库开发 | D7: =COUNTIFS(第一轮录入!$C$2:$C$505,A7,第一轮录入!$E$2:$E$505,">=1") -> 12 | E7: =COUNTIFS(第一轮录入!$C$2:$C$505,A7,第一轮录入!$E$2:$E$505,">=3") -> 12 | F7: =IF(D7=0,"",E7/D7) -> 1 | G7: =IF(D7=0,"",COMBIN(D7,E7)*0.5^D7) -> 0.00024414062 | H7: =IF(F7="","",(F7-G7)/(1-G7)) -> 1 | I7: 由分析脚本计算 | J7: 由分析脚本计算 | K7: =IF(D7<12,"数据未齐",IF(AND(F7>=10/12),"保留/检查IQR",IF(F7>=9/12,"修订进入R2","删除或合并候选"))) -> 保留/检查IQR | L7: 政策关键
A8: T07 | B8: 能力任务 | C8: 智能体设计与编排 | D8: =COUNTIFS(第一轮录入!$C$2:$C$505,A8,第一轮录入!$E$2:$E$505,">=1") -> 12 | E8: =COUNTIFS(第一轮录入!$C$2:$C$505,A8,第一轮录入!$E$2:$E$505,">=3") -> 12 | F8: =IF(D8=0,"",E8/D8) -> 1 | G8: =IF(D8=0,"",COMBIN(D8,E8)*0.5^D8) -> 0.00024414062 | H8: =IF(F8="","",(F8-G8)/(1-G8)) -> 1 | I8: 由分析脚本计算 | J8: 由分析脚本计算 | K8: =IF(D8<12,"数据未齐",IF(AND(F8>=10/12),"保留/检查IQR",IF(F8>=9/12,"修订进入R2","删除或合并候选"))) -> 保留/检查IQR | L8: 政策关键
A9: T08 | B9: 能力任务 | C9: 模型适配与多模态应用 | D9: =COUNTIFS(第一轮录入!$C$2:$C$505,A9,第一轮录入!$E$2:$E$505,">=1") -> 12 | E9: =COUNTIFS(第一轮录入!$C$2:$C$505,A9,第一轮录入!$E$2:$E$505,">=3") -> 12 | F9: =IF(D9=0,"",E9/D9) -> 1 | G9: =IF(D9=0,"",COMBIN(D9,E9)*0.5^D9) -> 0.00024414062 | H9: =IF(F9="","",(F9-G9)/(1-G9)) -> 1 | I9: 由分析脚本计算 | J9: 由分析脚本计算 | K9: =IF(D9<12,"数据未齐",IF(AND(F9>=10/12),"保留/检查IQR",IF(F9>=9/12,"修订进入R2","删除或合并候选"))) -> 保留/检查IQR
A10: T09 | B10: 能力任务 | C10: 数据来源、授权、隐私与敏感信息治理 | D10: =COUNTIFS(第一轮录入!$C$2:$C$505,A10,第一轮录入!$E$2:$E$505,">=1") -> 12 | E10: =COUNTIFS(第一轮录入!$C$2:$C$505,A10,第一轮录入!$E$2:$E$505,">=3") -> 12 | F10: =IF(D10=0,"",E10/D10) -> 1 | G10: =IF(D10=0,"",COMBIN(D10,E10)*0.5^D10) -> 0.00024414062 | H10: =IF(F10="","",(F10-G10)/(1-G10)) -> 1 | I10: 由分析脚本计算 | J10: 由分析脚本计算 | K10: =IF(D10<12,"数据未齐",IF(AND(F10>=10/12),"保留/检查IQR",IF(F10>=9/12,"修订进入R2","删除或合并候选"))) -> 保留/检查IQR | L10: 政策关键
A11: T10 | B11: 能力任务 | C11: 访问控制与最小权限 | D11: =COUNTIFS(第一轮录入!$C$2:$C$505,A11,第一轮录入!$E$2:$E$505,">=1") -> 12 | E11: =COUNTIFS(第一轮录入!$C$2:$C$505,A11,第一轮录入!$E$2:$E$505,">=3") -> 12 | F11: =IF(D11=0,"",E11/D11) -> 1 | G11: =IF(D11=0,"",COMBIN(D11,E11)*0.5^D11) -> 0.00024414062 | H11: =IF(F11="","",(F11-G11)/(1-G11)) -> 1 | I11: 由分析脚本计算 | J11: 由分析脚本计算 | K11: =IF(D11<12,"数据未齐",IF(AND(F11>=10/12),"保留/检查IQR",IF(F11>=9/12,"修订进入R2","删除或合并候选"))) -> 保留/检查IQR | L11: 政策关键
A12: T11 | B12: 能力任务 | C12: 幻觉与可靠性评估 | D12: =COUNTIFS(第一轮录入!$C$2:$C$505,A12,第一轮录入!$E$2:$E$505,">=1") -> 12 | E12: =COUNTIFS(第一轮录入!$C$2:$C$505,A12,第一轮录入!$E$2:$E$505,">=3") -> 12 | F12: =IF(D12=0,"",E12/D12) -> 1 | G12: =IF(D12=0,"",COMBIN(D12,E12)*0.5^D12) -> 0.00024414062 | H12: =IF(F12="","",(F12-G12)/(1-G12)) -> 1 | I12: 由分析脚本计算 | J12: 由分析脚本计算 | K12: =IF(D12<12,"数据未齐",IF(AND(F12>=10/12),"保留/检查IQR",IF(F12>=9/12,"修订进入R2","删除或合并候选"))) -> 保留/检查IQR | L12: 政策关键
A13: T12 | B13: 能力任务 | C13: 提示注入、越狱与对抗测试 | D13: =COUNTIFS(第一轮录入!$C$2:$C$505,A13,第一轮录入!$E$2:$E$505,">=1") -> 12 | E13: =COUNTIFS(第一轮录入!$C$2:$C$505,A13,第一轮录入!$E$2:$E$505,">=3") -> 12 | F13: =IF(D13=0,"",E13/D13) -> 1 | G13: =IF(D13=0,"",COMBIN(D13,E13)*0.5^D13) -> 0.00024414062 | H13: =IF(F13="","",(F13-G13)/(1-G13)) -> 1 | I13: 由分析脚本计算 | J13: 由分析脚本计算 | K13: =IF(D13<12,"数据未齐",IF(AND(F13>=10/12),"保留/检查IQR",IF(F13>=9/12,"修订进入R2","删除或合并候选"))) -> 保留/检查IQR | L13: 政策关键
A14: T13 | B14: 能力任务 | C14: 智能体工具调用与权限边界测试 | D14: =COUNTIFS(第一轮录入!$C$2:$C$505,A14,第一轮录入!$E$2:$E$505,">=1") -> 12 | E14: =COUNTIFS(第一轮录入!$C$2:$C$505,A14,第一轮录入!$E$2:$E$505,">=3") -> 12 | F14: =IF(D14=0,"",E14/D14) -> 1 | G14: =IF(D14=0,"",COMBIN(D14,E14)*0.5^D14) -> 0.00024414062 | H14: =IF(F14="","",(F14-G14)/(1-G14)) -> 1 | I14: 由分析脚本计算 | J14: 由分析脚本计算 | K14: =IF(D14<12,"数据未齐",IF(AND(F14>=10/12),"保留/检查IQR",IF(F14>=9/12,"修订进入R2","删除或合并候选"))) -> 保留/检查IQR | L14: 政策关键
A15: T14 | B15: 能力任务 | C15: 日志审计、监测与事件响应 | D15: =COUNTIFS(第一轮录入!$C$2:$C$505,A15,第一轮录入!$E$2:$E$505,">=1") -> 12 | E15: =COUNTIFS(第一轮录入!$C$2:$C$505,A15,第一轮录入!$E$2:$E$505,">=3") -> 12 | F15: =IF(D15=0,"",E15/D15) -> 1 | G15: =IF(D15=0,"",COMBIN(D15,E15)*0.5^D15) -> 0.00024414062 | H15: =IF(F15="","",(F15-G15)/(1-G15)) -> 1 | I15: 由分析脚本计算 | J15: 由分析脚本计算 | K15: =IF(D15<12,"数据未齐",IF(AND(F15>=10/12),"保留/检查IQR",IF(F15>=9/12,"修订进入R2","删除或合并候选"))) -> 保留/检查IQR | L15: 政策关键
A16: T15 | B16: 能力任务 | C16: 人工智能伦理与业务合规 | D16: =COUNTIFS(第一轮录入!$C$2:$C$505,A16,第一轮录入!$E$2:$E$505,">=1") -> 12 | E16: =COUNTIFS(第一轮录入!$C$2:$C$505,A16,第一轮录入!$E$2:$E$505,">=3") -> 12 | F16: =IF(D16=0,"",E16/D16) -> 1 | G16: =IF(D16=0,"",COMBIN(D16,E16)*0.5^D16) -> 0.00024414062 | H16: =IF(F16="","",(F16-G16)/(1-G16)) -> 1 | I16: 由分析脚本计算 | J16: 由分析脚本计算 | K16: =IF(D16<12,"数据未齐",IF(AND(F16>=10/12),"保留/检查IQR",IF(F16>=9/12,"修订进入R2","删除或合并候选"))) -> 保留/检查IQR | L16: 政策关键
A17: T16 | B17: 能力任务 | C17: 接口开发与系统集成 | D17: =COUNTIFS(第一轮录入!$C$2:$C$505,A17,第一轮录入!$E$2:$E$505,">=1") -> 12 | E17: =COUNTIFS(第一轮录入!$C$2:$C$505,A17,第一轮录入!$E$2:$E$505,">=3") -> 11 | F17: =IF(D17=0,"",E17/D17) -> 0.91666667 | G17: =IF(D17=0,"",COMBIN(D17,E17)*0.5^D17) -> 0.0029296875 | H17: =IF(F17="","",(F17-G17)/(1-G17)) -> 0.91642181 | I17: 由分析脚本计算 | J17: 由分析脚本计算 | K17: =IF(D17<12,"数据未齐",IF(AND(F17>=10/12),"保留/检查IQR",IF(F17>=9/12,"修订进入R2","删除或合并候选"))) -> 保留/检查IQR | L17: 政策关键
A18: T17 | B18: 能力任务 | C18: 容器化与云原生部署 | D18: =COUNTIFS(第一轮录入!$C$2:$C$505,A18,第一轮录入!$E$2:$E$505,">=1") -> 12 | E18: =COUNTIFS(第一轮录入!$C$2:$C$505,A18,第一轮录入!$E$2:$E$505,">=3") -> 11 | F18: =IF(D18=0,"",E18/D18) -> 0.91666667 | G18: =IF(D18=0,"",COMBIN(D18,E18)*0.5^D18) -> 0.0029296875 | H18: =IF(F18="","",(F18-G18)/(1-G18)) -> 0.91642181 | I18: 由分析脚本计算 | J18: 由分析脚本计算 | K18: =IF(D18<12,"数据未齐",IF(AND(F18>=10/12),"保留/检查IQR",IF(F18>=9/12,"修订进入R2","删除或合并候选"))) -> 保留/检查IQR | L18: 政策关键
A19: T18 | B19: 能力任务 | C19: 测试、上线与验收 | D19: =COUNTIFS(第一轮录入!$C$2:$C$505,A19,第一轮录入!$E$2:$E$505,">=1") -> 12 | E19: =COUNTIFS(第一轮录入!$C$2:$C$505,A19,第一轮录入!$E$2:$E$505,">=3") -> 12 | F19: =IF(D19=0,"",E19/D19) -> 1 | G19: =IF(D19=0,"",COMBIN(D19,E19)*0.5^D19) -> 0.00024414062 | H19: =IF(F19="","",(F19-G19)/(1-G19)) -> 1 | I19: 由分析脚本计算 | J19: 由分析脚本计算 | K19: =IF(D19<12,"数据未齐",IF(AND(F19>=10/12),"保留/检查IQR",IF(F19>=9/12,"修订进入R2","删除或合并候选"))) -> 保留/检查IQR | L19: 政策关键
A20: T19 | B20: 能力任务 | C20: 监控、运维与故障排查 | D20: =COUNTIFS(第一轮录入!$C$2:$C$505,A20,第一轮录入!$E$2:$E$505,">=1") -> 12 | E20: =COUNTIFS(第一轮录入!$C$2:$C$505,A20,第一轮录入!$E$2:$E$505,">=3") -> 12 | F20: =IF(D20=0,"",E20/D20) -> 1 | G20: =IF(D20=0,"",COMBIN(D20,E20)*0.5^D20) -> 0.00024414062 | H20: =IF(F20="","",(F20-G20)/(1-G20)) -> 1 | I20: 由分析脚本计算 | J20: 由分析脚本计算 | K20: =IF(D20<12,"数据未齐",IF(AND(F20>=10/12),"保留/检查IQR",IF(F20>=9/12,"修订进入R2","删除或合并候选"))) -> 保留/检查IQR | L20: 政策关键
A21: T20 | B21: 能力任务 | C21: 技术文档、用户培训与交接 | D21: =COUNTIFS(第一轮录入!$C$2:$C$505,A21,第一轮录入!$E$2:$E$505,">=1") -> 12 | E21: =COUNTIFS(第一轮录入!$C$2:$C$505,A21,第一轮录入!$E$2:$E$505,">=3") -> 12 | F21: =IF(D21=0,"",E21/D21) -> 1 | G21: =IF(D21=0,"",COMBIN(D21,E21)*0.5^D21) -> 0.00024414062 | H21: =IF(F21="","",(F21-G21)/(1-G21)) -> 1 | I21: 由分析脚本计算 | J21: 由分析脚本计算 | K21: =IF(D21<12,"数据未齐",IF(AND(F21>=10/12),"保留/检查IQR",IF(F21>=9/12,"修订进入R2","删除或合并候选"))) -> 保留/检查IQR | L21: 政策关键
... A30: C09 | B30: 课程模块 | C30: 项目交付管理与技术文档 | D30: =COUNTIFS(第一轮录入!$C$2:$C$505,A30,第一轮录入!$E$2:$E$505,">=1") -> 12 | E30: =COUNTIFS(第一轮录入!$C$2:$C$505,A30,第一轮录入!$E$2:$E$505,">=3") -> 12 | F30: =IF(D30=0,"",E30/D30) -> 1 | G30: =IF(D30=0,"",COMBIN(D30,E30)*0.5^D30) -> 0.00024414062 | H30: =IF(F30="","",(F30-G30)/(1-G30)) -> 1 | I30: 由分析脚本计算 | J30: 由分析脚本计算 | K30: =IF(D30<12,"数据未齐",IF(AND(F30>=10/12),"保留/检查IQR",IF(F30>=9/12,"修订进入R2","删除或合并候选"))) -> 保留/检查IQR | L30: 政策关键
A31: P01 | B31: 综合项目 | C31: 单一人工智能工具部署项目 | D31: =COUNTIFS(第一轮录入!$C$2:$C$505,A31,第一轮录入!$E$2:$E$505,">=1") -> 12 | E31: =COUNTIFS(第一轮录入!$C$2:$C$505,A31,第一轮录入!$E$2:$E$505,">=3") -> 12 | F31: =IF(D31=0,"",E31/D31) -> 1 | G31: =IF(D31=0,"",COMBIN(D31,E31)*0.5^D31) -> 0.00024414062 | H31: =IF(F31="","",(F31-G31)/(1-G31)) -> 1 | I31: 由分析脚本计算 | J31: 由分析脚本计算 | K31: =IF(D31<12,"数据未齐",IF(AND(F31>=10/12),"保留/检查IQR",IF(F31>=9/12,"修订进入R2","删除或合并候选"))) -> 保留/检查IQR
A32: P02 | B32: 综合项目 | C32: 行业知识库与RAG项目 | D32: =COUNTIFS(第一轮录入!$C$2:$C$505,A32,第一轮录入!$E$2:$E$505,">=1") -> 12 | E32: =COUNTIFS(第一轮录入!$C$2:$C$505,A32,第一轮录入!$E$2:$E$505,">=3") -> 12 | F32: =IF(D32=0,"",E32/D32) -> 1 | G32: =IF(D32=0,"",COMBIN(D32,E32)*0.5^D32) -> 0.00024414062 | H32: =IF(F32="","",(F32-G32)/(1-G32)) -> 1 | I32: 由分析脚本计算 | J32: 由分析脚本计算 | K32: =IF(D32<12,"数据未齐",IF(AND(F32>=10/12),"保留/检查IQR",IF(F32>=9/12,"修订进入R2","删除或合并候选"))) -> 保留/检查IQR | L32: 政策关键
A33: P03 | B33: 综合项目 | C33: 智能体业务流程改造项目 | D33: =COUNTIFS(第一轮录入!$C$2:$C$505,A33,第一轮录入!$E$2:$E$505,">=1") -> 12 | E33: =COUNTIFS(第一轮录入!$C$2:$C$505,A33,第一轮录入!$E$2:$E$505,">=3") -> 12 | F33: =IF(D33=0,"",E33/D33) -> 1 | G33: =IF(D33=0,"",COMBIN(D33,E33)*0.5^D33) -> 0.00024414062 | H33: =IF(F33="","",(F33-G33)/(1-G33)) -> 1 | I33: 由分析脚本计算 | J33: 由分析脚本计算 | K33: =IF(D33<12,"数据未齐",IF(AND(F33>=10/12),"保留/检查IQR",IF(F33>=9/12,"修订进入R2","删除或合并候选"))) -> 保留/检查IQR | L33: 政策关键
A34: P04 | B34: 综合项目 | C34: 综合人工智能应用交付项目 | D34: =COUNTIFS(第一轮录入!$C$2:$C$505,A34,第一轮录入!$E$2:$E$505,">=1") -> 12 | E34: =COUNTIFS(第一轮录入!$C$2:$C$505,A34,第一轮录入!$E$2:$E$505,">=3") -> 12 | F34: =IF(D34=0,"",E34/D34) -> 1 | G34: =IF(D34=0,"",COMBIN(D34,E34)*0.5^D34) -> 0.00024414062 | H34: =IF(F34="","",(F34-G34)/(1-G34)) -> 1 | I34: 由分析脚本计算 | J34: 由分析脚本计算 | K34: =IF(D34<12,"数据未齐",IF(AND(F34>=10/12),"保留/检查IQR",IF(F34>=9/12,"修订进入R2","删除或合并候选"))) -> 保留/检查IQR | L34: 政策关键
A35: E01 | B35: 评价证据 | C35: 需求规格说明书 | D35: =COUNTIFS(第一轮录入!$C$2:$C$505,A35,第一轮录入!$E$2:$E$505,">=1") -> 12 | E35: =COUNTIFS(第一轮录入!$C$2:$C$505,A35,第一轮录入!$E$2:$E$505,">=3") -> 12 | F35: =IF(D35=0,"",E35/D35) -> 1 | G35: =IF(D35=0,"",COMBIN(D35,E35)*0.5^D35) -> 0.00024414062 | H35: =IF(F35="","",(F35-G35)/(1-G35)) -> 1 | I35: 由分析脚本计算 | J35: 由分析脚本计算 | K35: =IF(D35<12,"数据未齐",IF(AND(F35>=10/12),"保留/检查IQR",IF(F35>=9/12,"修订进入R2","删除或合并候选"))) -> 保留/检查IQR | L35: 政策关键
A36: E02 | B36: 评价证据 | C36: 业务流程图与场景分析报告 | D36: =COUNTIFS(第一轮录入!$C$2:$C$505,A36,第一轮录入!$E$2:$E$505,">=1") -> 12 | E36: =COUNTIFS(第一轮录入!$C$2:$C$505,A36,第一轮录入!$E$2:$E$505,">=3") -> 12 | F36: =IF(D36=0,"",E36/D36) -> 1 | G36: =IF(D36=0,"",COMBIN(D36,E36)*0.5^D36) -> 0.00024414062 | H36: =IF(F36="","",(F36-G36)/(1-G36)) -> 1 | I36: 由分析脚本计算 | J36: 由分析脚本计算 | K36: =IF(D36<12,"数据未齐",IF(AND(F36>=10/12),"保留/检查IQR",IF(F36>=9/12,"修订进入R2","删除或合并候选"))) -> 保留/检查IQR | L36: 政策关键
A37: E03 | B37: 评价证据 | C37: 模型选型与技术方案报告 | D37: =COUNTIFS(第一轮录入!$C$2:$C$505,A37,第一轮录入!$E$2:$E$505,">=1") -> 12 | E37: =COUNTIFS(第一轮录入!$C$2:$C$505,A37,第一轮录入!$E$2:$E$505,">=3") -> 12 | F37: =IF(D37=0,"",E37/D37) -> 1 | G37: =IF(D37=0,"",COMBIN(D37,E37)*0.5^D37) -> 0.00024414062 | H37: =IF(F37="","",(F37-G37)/(1-G37)) -> 1 | I37: 由分析脚本计算 | J37: 由分析脚本计算 | K37: =IF(D37<12,"数据未齐",IF(AND(F37>=10/12),"保留/检查IQR",IF(F37>=9/12,"修订进入R2","删除或合并候选"))) -> 保留/检查IQR | L37: 政策关键
A38: E04 | B38: 评价证据 | C38: RAG/智能体运行与评测记录 | D38: =COUNTIFS(第一轮录入!$C$2:$C$505,A38,第一轮录入!$E$2:$E$505,">=1") -> 12 | E38: =COUNTIFS(第一轮录入!$C$2:$C$505,A38,第一轮录入!$E$2:$E$505,">=3") -> 12 | F38: =IF(D38=0,"",E38/D38) -> 1 | G38: =IF(D38=0,"",COMBIN(D38,E38)*0.5^D38) -> 0.00024414062 | H38: =IF(F38="","",(F38-G38)/(1-G38)) -> 1 | I38: 由分析脚本计算 | J38: 由分析脚本计算 | K38: =IF(D38<12,"数据未齐",IF(AND(F38>=10/12),"保留/检查IQR",IF(F38>=9/12,"修订进入R2","删除或合并候选"))) -> 保留/检查IQR | L38: 政策关键
A39: E05 | B39: 评价证据 | C39: 数据清单、授权与隐私处理记录 | D39: =COUNTIFS(第一轮录入!$C$2:$C$505,A39,第一轮录入!$E$2:$E$505,">=1") -> 12 | E39: =COUNTIFS(第一轮录入!$C$2:$C$505,A39,第一轮录入!$E$2:$E$505,">=3") -> 12 | F39: =IF(D39=0,"",E39/D39) -> 1 | G39: =IF(D39=0,"",COMBIN(D39,E39)*0.5^D39) -> 0.00024414062 | H39: =IF(F39="","",(F39-G39)/(1-G39)) -> 1 | I39: 由分析脚本计算 | J39: 由分析脚本计算 | K39: =IF(D39<12,"数据未齐",IF(AND(F39>=10/12),"保留/检查IQR",IF(F39>=9/12,"修订进入R2","删除或合并候选"))) -> 保留/检查IQR | L39: 政策关键
A40: E06 | B40: 评价证据 | C40: 安全风险评估与测试报告 | D40: =COUNTIFS(第一轮录入!$C$2:$C$505,A40,第一轮录入!$E$2:$E$505,">=1") -> 12 | E40: =COUNTIFS(第一轮录入!$C$2:$C$505,A40,第一轮录入!$E$2:$E$505,">=3") -> 12 | F40: =IF(D40=0,"",E40/D40) -> 1 | G40: =IF(D40=0,"",COMBIN(D40,E40)*0.5^D40) -> 0.00024414062 | H40: =IF(F40="","",(F40-G40)/(1-G40)) -> 1 | I40: 由分析脚本计算 | J40: 由分析脚本计算 | K40: =IF(D40<12,"数据未齐",IF(AND(F40>=10/12),"保留/检查IQR",IF(F40>=9/12,"修订进入R2","删除或合并候选"))) -> 保留/检查IQR | L40: 政策关键
A41: E07 | B41: 评价证据 | C41: 代码仓库、构建与部署记录 | D41: =COUNTIFS(第一轮录入!$C$2:$C$505,A41,第一轮录入!$E$2:$E$505,">=1") -> 12 | E41: =COUNTIFS(第一轮录入!$C$2:$C$505,A41,第一轮录入!$E$2:$E$505,">=3") -> 12 | F41: =IF(D41=0,"",E41/D41) -> 1 | G41: =IF(D41=0,"",COMBIN(D41,E41)*0.5^D41) -> 0.00024414062 | H41: =IF(F41="","",(F41-G41)/(1-G41)) -> 1 | I41: 由分析脚本计算 | J41: 由分析脚本计算 | K41: =IF(D41<12,"数据未齐",IF(AND(F41>=10/12),"保留/检查IQR",IF(F41>=9/12,"修订进入R2","删除或合并候选"))) -> 保留/检查IQR | L41: 政策关键
A42: E08 | B42: 评价证据 | C42: 监控、运维与事件处置记录 | D42: =COUNTIFS(第一轮录入!$C$2:$C$505,A42,第一轮录入!$E$2:$E$505,">=1") -> 12 | E42: =COUNTIFS(第一轮录入!$C$2:$C$505,A42,第一轮录入!$E$2:$E$505,">=3") -> 12 | F42: =IF(D42=0,"",E42/D42) -> 1 | G42: =IF(D42=0,"",COMBIN(D42,E42)*0.5^D42) -> 0.00024414062 | H42: =IF(F42="","",(F42-G42)/(1-G42)) -> 1 | I42: 由分析脚本计算 | J42: 由分析脚本计算 | K42: =IF(D42<12,"数据未齐",IF(AND(F42>=10/12),"保留/检查IQR",IF(F42>=9/12,"修订进入R2","删除或合并候选"))) -> 保留/检查IQR | L42: 政策关键
A43: E09 | B43: 评价证据 | C43: 用户手册、培训与验收材料 | D43: =COUNTIFS(第一轮录入!$C$2:$C$505,A43,第一轮录入!$E$2:$E$505,">=1") -> 12 | E43: =COUNTIFS(第一轮录入!$C$2:$C$505,A43,第一轮录入!$E$2:$E$505,">=3") -> 12 | F43: =IF(D43=0,"",E43/D43) -> 1 | G43: =IF(D43=0,"",COMBIN(D43,E43)*0.5^D43) -> 0.00024414062 | H43: =IF(F43="","",(F43-G43)/(1-G43)) -> 1 | I43: 由分析脚本计算 | J43: 由分析脚本计算 | K43: =IF(D43<12,"数据未齐",IF(AND(F43>=10/12),"保留/检查IQR",IF(F43>=9/12,"修订进入R2","删除或合并候选"))) -> 保留/检查IQR | L43: 政策关键
A45: S-CVI/Ave | B45: =AVERAGE(F2:F43) -> 0.99404762

Sheet 条目修订日志
A1: 条目编号 | B1: 轮次 | C1: 原文本 | D1: 统计摘要 | E1: 支持意见摘要 | F1: 保留/反对意见摘要 | G1: 决策 | H1: 修订文本 | I1: 决策理由 | J1: 复核人 | K1: 日期
A2: T01 | B2: R1 | C2: 需求沟通与需求分析：能够通过访谈、观察和资料分析形成可验证的业务需求。 | D2: I-CVI=1.000；D1中位数=4.0，IQR=0.00，同意数=12/12；D2/D3/D4/D5中位数=4.0/4.0/4.0/3.5 | E2: D1内容相关性I-CVI=1.000、中位数=4.0，达到保留阈值（≥0.78）。 | F2: [E06] 增加需求可测试性和优先级确认。；[V05] 邀请企业参与需求评审，增强职业情境。 | G2: 修订进入R2 | H2: 能够通过访谈、观察和资料分析，形成含验收标准与优先级的可测试业务需求，并参与企业需求评审。 | I2: 符合纳入标准（≥2条文字意见 或 ≥3位专家在任一维度给≤2分），纳入第二轮复评确认。 | K2: 2026-10-08
A3: T02 | B3: R1 | C3: 行业流程与应用场景分析：能够识别流程痛点、数据条件及人工智能适用边界。 | D3: I-CVI=0.917；D1中位数=4.0，IQR=0.00，同意数=11/12；D2/D3/D4/D5中位数=4.0/4.0/4.0/4.0 | E3: D1内容相关性I-CVI=0.917、中位数=4.0，达到保留阈值（≥0.78）。 | F3: [V04] 建议明确可观察的流程分析产出。 | G3: 保留 | I3: 未达纳入第二轮阈值（文字意见<2条且低分专家<3人），且I-CVI≥0.78，保留原条目。 | K3: 2026-10-08
A4: T03 | B4: R1 | C4: 解决方案设计与项目协同：能够形成技术—业务方案并参与范围、进度和风险协调。 | D4: I-CVI=1.000；D1中位数=3.0，IQR=1.00，同意数=12/12；D2/D3/D4/D5中位数=4.0/3.5/4.0/4.0 | E4: D1内容相关性I-CVI=1.000、中位数=3.0，达到保留阈值（≥0.78）。 | F4: [E01] 补充变更控制与里程碑验收。；[V01] 范围、进度和风险可下沉到综合项目训练。 | G4: 修订进入R2 | H4: 能够形成技术—业务方案，明确里程碑与变更控制机制，并参与范围、进度和风险协调。 | I4: 符合纳入标准（≥2条文字意见 或 ≥3位专家在任一维度给≤2分），纳入第二轮复评确认。 | K4: 2026-10-08
A5: T04 | B5: R1 | C5: 模型能力边界评估与选型：能够依据任务、成本、安全和部署约束选择模型。 | D5: I-CVI=1.000；D1中位数=3.0，IQR=1.00，同意数=12/12；D2/D3/D4/D5中位数=3.5/4.0/3.0/4.0 | E5: D1内容相关性I-CVI=1.000、中位数=3.0，达到保留阈值（≥0.78）。 | F5: 无（未提出文字修改意见） | G5: 保留 | I5: 未达纳入第二轮阈值（文字意见<2条且低分专家<3人），且I-CVI≥0.78，保留原条目。 | K5: 2026-10-08
A6: T05 | B6: R1 | C6: 大模型与提示词应用开发：能够设计、实现和测试基于大模型的应用功能。 | D6: I-CVI=1.000；D1中位数=4.0，IQR=0.00，同意数=12/12；D2/D3/D4/D5中位数=4.0/4.0/4.0/4.0 | E6: D1内容相关性I-CVI=1.000、中位数=4.0，达到保留阈值（≥0.78）。 | F6: [V02] 突出调用、调试和评测，不宜过度讲底层训练。 | G6: 保留 | I6: 未达纳入第二轮阈值（文字意见<2条且低分专家<3人），且I-CVI≥0.78，保留原条目。 | K6: 2026-10-08
A7: T06 | B7: R1 | C7: 检索增强生成与知识库开发：能够完成数据处理、索引、检索、生成和效果评估。 | D7: I-CVI=1.000；D1中位数=4.0，IQR=0.00，同意数=12/12；D2/D3/D4/D5中位数=4.0/4.0/4.0/4.0 | E7: D1内容相关性I-CVI=1.000、中位数=4.0，达到保留阈值（≥0.78）。 | F7: [E04] 增加检索召回、引用正确率和更新时效指标。；[V02] 提供可复用语料包和基准问题集。 | G7: 修订进入R2 | H7: 能够完成数据处理、索引、检索、生成和效果评估，并以基准问题集度量检索召回率、引用正确率与更新时效。 | I7: 符合纳入标准（≥2条文字意见 或 ≥3位专家在任一维度给≤2分），纳入第二轮复评确认。 | K7: 2026-10-08
A8: T07 | B8: R1 | C8: 智能体设计与编排：能够设计任务分解、工具调用、状态管理及人工介入机制。 | D8: I-CVI=1.000；D1中位数=4.0，IQR=1.00，同意数=12/12；D2/D3/D4/D5中位数=4.0/4.0/3.0/4.0 | E8: D1内容相关性I-CVI=1.000、中位数=4.0，达到保留阈值（≥0.78）。 | F8: [E05] 补充终止条件、超时和状态恢复。 | G8: 保留 | I8: 未达纳入第二轮阈值（文字意见<2条且低分专家<3人），且I-CVI≥0.78，保留原条目。 | K8: 2026-10-08
A9: T08 | B9: R1 | C9: 模型适配与多模态应用：能够根据场景开展轻量化微调或多模态能力集成。 | D9: I-CVI=1.000；D1中位数=3.0，IQR=1.00，同意数=12/12；D2/D3/D4/D5中位数=4.0/3.0/3.0/4.0 | E9: D1内容相关性I-CVI=1.000、中位数=3.0，达到保留阈值（≥0.78）。 | F9: [E02] 微调可作为选学，多模态集成应突出接口调用。；[V01] 微调部分建议设置为拓展任务。；另低分：[E01] D4=2；[E02] D4=2；[E03] D4=2；[V04] D3=2；[V05] D3=2、D4=2 | G9: 修订进入R2 | H9: 能够根据场景集成多模态能力（以接口调用为主）；轻量化微调作为拓展／选学任务，不作为必达要求。 | I9: 符合纳入标准（≥2条文字意见 或 ≥3位专家在任一维度给≤2分），纳入第二轮复评确认。 | K9: 2026-10-08
A10: T09 | B10: R1 | C10: 数据来源、授权、隐私与敏感信息治理：能够核验数据合法来源、授权边界并落实隐私保护。 | D10: I-CVI=1.000；D1中位数=4.0，IQR=0.00，同意数=12/12；D2/D3/D4/D5中位数=4.0/4.0/4.0/4.0 | E10: D1内容相关性I-CVI=1.000、中位数=4.0，达到保留阈值（≥0.78）。 | F10: [E03] 增加数据保留期限和删除机制。 | G10: 保留 | I10: 未达纳入第二轮阈值（文字意见<2条且低分专家<3人），且I-CVI≥0.78，保留原条目。 | K10: 2026-10-08
A11: T10 | B11: R1 | C11: 访问控制与最小权限：能够为用户、服务和智能体配置身份、权限及密钥管理。 | D11: I-CVI=1.000；D1中位数=4.0，IQR=0.00，同意数=12/12；D2/D3/D4/D5中位数=4.0/4.0/4.0/4.0 | E11: D1内容相关性I-CVI=1.000、中位数=4.0，达到保留阈值（≥0.78）。 | F11: [V03] 密钥管理需使用专用保管方式，禁止写入代码。 | G11: 保留 | I11: 未达纳入第二轮阈值（文字意见<2条且低分专家<3人），且I-CVI≥0.78，保留原条目。 | K11: 2026-10-08
A12: T11 | B12: R1 | C12: 幻觉与可靠性评估：能够建立事实性、稳定性、可追溯性和拒答能力测试。 | D12: I-CVI=1.000；D1中位数=4.0，IQR=0.00，同意数=12/12；D2/D3/D4/D5中位数=4.0/4.0/4.0/4.0 | E12: D1内容相关性I-CVI=1.000、中位数=4.0，达到保留阈值（≥0.78）。 | F12: [E04] 可靠性评估应按业务风险设置通过阈值。；[V04] 可靠性指标需给出最低样本量。 | G12: 修订进入R2 | H12: 能够建立事实性、稳定性、可追溯性和拒答能力测试，并按业务风险设定通过阈值与最低样本量。 | I12: 符合纳入标准（≥2条文字意见 或 ≥3位专家在任一维度给≤2分），纳入第二轮复评确认。 | K12: 2026-10-08
A13: T12 | B13: R1 | C13: 提示注入、越狱与对抗测试：能够识别并测试恶意提示、间接注入和防护措施。 | D13: I-CVI=1.000；D1中位数=3.5，IQR=1.00，同意数=12/12；D2/D3/D4/D5中位数=4.0/4.0/3.0/4.0 | E13: D1内容相关性I-CVI=1.000、中位数=3.5，达到保留阈值（≥0.78）。 | F13: [E03] 对抗测试必须限定授权范围并保留记录。；[V03] 先讲授权和安全边界，再开展对抗测试。；另低分：[E02] D4=2；[V01] D3=2；[V02] D3=2 | G13: 修订进入R2 | H13: 在授权范围内识别并测试恶意提示、间接注入和防护措施；测试须限定授权范围并保留记录。 | I13: 符合纳入标准（≥2条文字意见 或 ≥3位专家在任一维度给≤2分），纳入第二轮复评确认。 | K13: 2026-10-08
A14: T13 | B14: R1 | C14: 智能体工具调用与权限边界测试：能够验证工具白名单、参数约束、确认机制和异常处置。 | D14: I-CVI=1.000；D1中位数=4.0，IQR=1.00，同意数=12/12；D2/D3/D4/D5中位数=3.5/4.0/3.0/4.0 | E14: D1内容相关性I-CVI=1.000、中位数=4.0，达到保留阈值（≥0.78）。 | F14: [E01] 明确高风险工具调用须人工确认。；[E05] 工具参数校验应列为必测项。 | G14: 修订进入R2 | H14: 能够验证工具白名单、参数约束与异常处置，明确高风险工具调用须经人工确认；工具参数校验列为必测项。 | I14: 符合纳入标准（≥2条文字意见 或 ≥3位专家在任一维度给≤2分），纳入第二轮复评确认。 | K14: 2026-10-08
A15: T14 | B15: R1 | C15: 日志审计、监测与事件响应：能够保留关键日志、识别异常并执行响应和复盘。 | D15: I-CVI=1.000；D1中位数=3.5，IQR=1.00，同意数=12/12；D2/D3/D4/D5中位数=4.0/3.0/3.0/4.0 | E15: D1内容相关性I-CVI=1.000、中位数=3.5，达到保留阈值（≥0.78）。 | F15: [E05] 增加人工接管后的事件复盘。 | G15: 保留 | I15: 未达纳入第二轮阈值（文字意见<2条且低分专家<3人），且I-CVI≥0.78，保留原条目。 | K15: 2026-10-08
A16: T15 | B16: R1 | C16: 人工智能伦理与业务合规：能够识别偏见、版权、责任边界及行业合规要求。 | D16: I-CVI=1.000；D1中位数=4.0，IQR=0.00，同意数=12/12；D2/D3/D4/D5中位数=4.0/4.0/3.5/4.0 | E16: D1内容相关性I-CVI=1.000、中位数=4.0，达到保留阈值（≥0.78）。 | F16: [E03] 应覆盖生成内容标识、版权和责任追溯。；[V03] 增加案例讨论和责任角色辨析。 | G16: 修订进入R2 | H16: 能够识别偏见、版权、责任边界及行业合规要求，覆盖生成内容标识与责任追溯，并通过案例辨析责任角色。 | I16: 符合纳入标准（≥2条文字意见 或 ≥3位专家在任一维度给≤2分），纳入第二轮复评确认。 | K16: 2026-10-08
A17: T16 | B17: R1 | C17: 接口开发与系统集成：能够通过API、数据库和消息机制集成既有系统。 | D17: I-CVI=0.917；D1中位数=4.0，IQR=0.00，同意数=11/12；D2/D3/D4/D5中位数=4.0/4.0/4.0/3.5 | E17: D1内容相关性I-CVI=0.917、中位数=4.0，达到保留阈值（≥0.78）。 | F17: [E01] D1 内容相关性=1、D3=1、D5=2；[V01] D2=1、D5=2 | G17: 保留 | I17: 未达纳入第二轮阈值（文字意见<2条且低分专家<3人），且I-CVI≥0.78，保留原条目。 | K17: 2026-10-08
A18: T17 | B18: R1 | C18: 容器化与云原生部署：能够完成镜像、配置、服务发布、资源管理和回滚。 | D18: I-CVI=0.917；D1中位数=3.0，IQR=1.00，同意数=11/12；D2/D3/D4/D5中位数=4.0/3.5/3.0/4.0 | E18: D1内容相关性I-CVI=0.917、中位数=3.0，达到保留阈值（≥0.78）。 | F18: [E02] 增加资源限额、弹性伸缩和灰度发布。；[V02] 容器编排深度应控制在高职可操作范围。；[V06] 建议兼顾单机容器与集群部署两级任务。；另低分：[E02] D4=2；[V01] D1 内容相关性=2；[V04] D4=2；[V05] D4=2；[V06] D3=2 | G18: 修订进入R2 | H18: 能够完成镜像、配置、资源限额、服务发布、灰度发布与回滚；以单机容器为基础、集群部署为拓展，深度控制在高职可操作范围。 | I18: 符合纳入标准（≥2条文字意见 或 ≥3位专家在任一维度给≤2分），纳入第二轮复评确认。 | K18: 2026-10-08
A19: T18 | B19: R1 | C19: 测试、上线与验收：能够制定测试方案，支持上线并依据指标组织验收。 | D19: I-CVI=1.000；D1中位数=4.0，IQR=0.00，同意数=12/12；D2/D3/D4/D5中位数=4.0/4.0/4.0/4.0 | E19: D1内容相关性I-CVI=1.000、中位数=4.0，达到保留阈值（≥0.78）。 | F19: [E06] 验收指标应在开发前共同确定。 | G19: 保留 | I19: 未达纳入第二轮阈值（文字意见<2条且低分专家<3人），且I-CVI≥0.78，保留原条目。 | K19: 2026-10-08
A20: T19 | B20: R1 | C20: 监控、运维与故障排查：能够监控质量、时延、成本和安全指标并定位故障。 | D20: I-CVI=1.000；D1中位数=3.5，IQR=1.00，同意数=12/12；D2/D3/D4/D5中位数=3.5/3.0/3.0/4.0 | E20: D1内容相关性I-CVI=1.000、中位数=3.5，达到保留阈值（≥0.78）。 | F20: [E02] 监控指标应区分模型质量与平台可用性。；[V06] 提供预设故障和可观察指标。；另低分：[E05] D4=2；[V01] D3=2；[V05] D4=2；[V06] D4=2 | G20: 修订进入R2 | H20: 能够监控模型质量与平台可用性两类指标（含质量、时延、成本、安全）并定位故障；配套预设故障与可观察指标。 | I20: 符合纳入标准（≥2条文字意见 或 ≥3位专家在任一维度给≤2分），纳入第二轮复评确认。 | K20: 2026-10-08
A21: T20 | B21: R1 | C21: 技术文档、用户培训与交接：能够形成可维护文档并完成培训、交接和知识转移。 | D21: I-CVI=1.000；D1中位数=3.0，IQR=1.00，同意数=12/12；D2/D3/D4/D5中位数=4.0/4.0/4.0/4.0 | E21: D1内容相关性I-CVI=1.000、中位数=3.0，达到保留阈值（≥0.78）。 | F21: [E06] 培训材料应区分管理员和普通用户。；[V05] 交接环节可由企业导师模拟签收。 | G21: 修订进入R2 | H21: 能够形成可维护文档，面向管理员与普通用户分层培训，并完成可由企业导师模拟签收的交接与知识转移。 | I21: 符合纳入标准（≥2条文字意见 或 ≥3位专家在任一维度给≤2分），纳入第二轮复评确认。 | K21: 2026-10-08
A22: C01 | B22: R1 | C22: 行业人工智能解决方案设计：面向真实行业问题完成场景识别、价值判断与总体方案设计。 | D22: I-CVI=1.000；D1中位数=3.0，IQR=1.00，同意数=12/12；D2/D3/D4/D5中位数=4.0/4.0/4.0/4.0 | E22: D1内容相关性I-CVI=1.000、中位数=3.0，达到保留阈值（≥0.78）。 | F22: [V01] 需给出适合高职的场景复杂度边界。 | G22: 保留 | I22: 未达纳入第二轮阈值（文字意见<2条且低分专家<3人），且I-CVI≥0.78，保留原条目。 | K22: 2026-10-08
A23: C02 | B23: R1 | C23: 需求分析与客户沟通：训练访谈、流程建模、需求规格和范围确认。 | D23: I-CVI=1.000；D1中位数=4.0，IQR=0.00，同意数=12/12；D2/D3/D4/D5中位数=4.0/4.0/4.0/4.0 | E23: D1内容相关性I-CVI=1.000、中位数=4.0，达到保留阈值（≥0.78）。 | F23: 无（未提出文字修改意见） | G23: 保留 | I23: 未达纳入第二轮阈值（文字意见<2条且低分专家<3人），且I-CVI≥0.78，保留原条目。 | K23: 2026-10-08
A24: C03 | B24: R1 | C24: 大模型应用与提示工程：训练大模型调用、提示设计、评测与应用开发。 | D24: I-CVI=1.000；D1中位数=4.0，IQR=0.00，同意数=12/12；D2/D3/D4/D5中位数=4.0/4.0/4.0/4.0 | E24: D1内容相关性I-CVI=1.000、中位数=4.0，达到保留阈值（≥0.78）。 | F24: [V02] 增加结构化输出与提示版本管理。 | G24: 保留 | I24: 未达纳入第二轮阈值（文字意见<2条且低分专家<3人），且I-CVI≥0.78，保留原条目。 | K24: 2026-10-08
A25: C04 | B25: R1 | C25: RAG与企业知识库：训练语料治理、检索、生成、评测和持续维护。 | D25: I-CVI=1.000；D1中位数=4.0，IQR=0.00，同意数=12/12；D2/D3/D4/D5中位数=4.0/4.0/4.0/4.0 | E25: D1内容相关性I-CVI=1.000、中位数=4.0，达到保留阈值（≥0.78）。 | F25: [E04] 加入文档更新、失效与权限继承。 | G25: 保留 | I25: 未达纳入第二轮阈值（文字意见<2条且低分专家<3人），且I-CVI≥0.78，保留原条目。 | K25: 2026-10-08
A26: C05 | B26: R1 | C26: 智能体设计与业务流程编排：训练任务规划、工具调用、权限控制和人机协同。 | D26: I-CVI=1.000；D1中位数=3.0，IQR=0.25，同意数=12/12；D2/D3/D4/D5中位数=4.0/4.0/3.0/4.0 | E26: D1内容相关性I-CVI=1.000、中位数=3.0，达到保留阈值（≥0.78）。 | F26: [E05] 先做单智能体，再做多步骤流程。；另低分：[E01] D5=2；[E04] D4=2；[V01] D4=2；[V02] D4=2；[V06] D4=2 | G26: 修订进入R2 | H26: 训练任务规划、工具调用、权限控制和人机协同；按“先单智能体、再多步骤流程”的梯度组织，降低编排复杂度。 | I26: 符合纳入标准（≥2条文字意见 或 ≥3位专家在任一维度给≤2分），纳入第二轮复评确认。 | K26: 2026-10-08
A27: C06 | B27: R1 | C27: 人工智能安全、隐私与合规：覆盖数据、模型、应用、智能体和业务治理。 | D27: I-CVI=1.000；D1中位数=4.0，IQR=0.00，同意数=12/12；D2/D3/D4/D5中位数=4.0/4.0/3.0/4.0 | E27: D1内容相关性I-CVI=1.000、中位数=4.0，达到保留阈值（≥0.78）。 | F27: [E03] 建议以风险评估贯穿其他模块。；[V03] 应与所有项目共用检查清单。；另低分：[E01] D3=1、D4=2；[V01] D2=2、D4=2；[V02] D3=2 | G27: 修订进入R2 | H27: 覆盖数据、模型、应用、智能体和业务治理；以风险评估贯穿其他模块，并与各项目共用统一检查清单。 | I27: 符合纳入标准（≥2条文字意见 或 ≥3位专家在任一维度给≤2分），纳入第二轮复评确认。 | K27: 2026-10-08
A28: C07 | B28: R1 | C28: 云原生部署与系统集成：训练API、容器、服务编排、发布和回滚。 | D28: I-CVI=1.000；D1中位数=3.5，IQR=1.00，同意数=12/12；D2/D3/D4/D5中位数=3.0/3.0/3.0/4.0 | E28: D1内容相关性I-CVI=1.000、中位数=3.5，达到保留阈值（≥0.78）。 | F28: [E02] 建议使用轻量集群或托管平台降低门槛。；[V06] 注明最低算力、网络和平台条件。；另低分：[E04] D4=2；[E06] D4=2；[V01] D4=2；[V04] D4=2 | G28: 修订进入R2 | H28: 训练API、容器、服务编排、发布和回滚；采用轻量集群或托管平台降低门槛，并注明最低算力、网络与平台条件。 | I28: 符合纳入标准（≥2条文字意见 或 ≥3位专家在任一维度给≤2分），纳入第二轮复评确认。 | K28: 2026-10-08
A29: C08 | B29: R1 | C29: 智能应用运维与质量监测：训练日志、监控、质量评估、成本管理和事件响应。 | D29: I-CVI=1.000；D1中位数=3.0，IQR=1.00，同意数=12/12；D2/D3/D4/D5中位数=4.0/3.5/3.0/3.0 | E29: D1内容相关性I-CVI=1.000、中位数=3.0，达到保留阈值（≥0.78）。 | F29: [E01] 增加成本预算与告警阈值训练。；[V06] 增加成本监测和资源回收。；另低分：[E04] D4=2；[V03] D4=2；[V04] D4=2；[V06] D3=2 | G29: 修订进入R2 | H29: 训练日志、监控、质量评估、成本预算与资源回收、告警阈值设定和事件响应。 | I29: 符合纳入标准（≥2条文字意见 或 ≥3位专家在任一维度给≤2分），纳入第二轮复评确认。 | K29: 2026-10-08
A30: C09 | B30: R1 | C30: 项目交付管理与技术文档：训练项目协同、测试验收、文档、培训和交接。 | D30: I-CVI=1.000；D1中位数=4.0，IQR=0.25，同意数=12/12；D2/D3/D4/D5中位数=4.0/3.5/3.5/4.0 | E30: D1内容相关性I-CVI=1.000、中位数=4.0，达到保留阈值（≥0.78）。 | F30: [E06] 建议加入变更记录与遗留问题清单。；[V05] 增加企业评审节点和沟通记录。 | G30: 修订进入R2 | H30: 训练项目协同、测试验收、变更记录与遗留问题清单、文档、培训和交接，并设置企业评审节点与沟通记录。 | I30: 符合纳入标准（≥2条文字意见 或 ≥3位专家在任一维度给≤2分），纳入第二轮复评确认。 | K30: 2026-10-08
A31: P01 | B31: R1 | C31: 单一人工智能工具部署项目：完成受控场景下的模型/API接入、部署、测试和说明。 | D31: I-CVI=1.000；D1中位数=3.5，IQR=1.00，同意数=12/12；D2/D3/D4/D5中位数=3.0/4.0/4.0/4.0 | E31: D1内容相关性I-CVI=1.000、中位数=3.5，达到保留阈值（≥0.78）。 | F31: [V02] 适合作为前置小项目。 | G31: 保留 | I31: 未达纳入第二轮阈值（文字意见<2条且低分专家<3人），且I-CVI≥0.78，保留原条目。 | K31: 2026-10-08
A32: P02 | B32: R1 | C32: 行业知识库与RAG项目：完成授权语料治理、检索生成、效果评估和迭代。 | D32: I-CVI=1.000；D1中位数=4.0，IQR=0.00，同意数=12/12；D2/D3/D4/D5中位数=4.0/4.0/4.0/4.0 | E32: D1内容相关性I-CVI=1.000、中位数=4.0，达到保留阈值（≥0.78）。 | F32: [E04] 需设置可验证问题集和人工复核样本。；[V05] 语料应由企业脱敏后提供或共同构造。 | G32: 修订进入R2 | H32: 完成授权语料治理（企业脱敏提供或共同构造）、检索生成，并以可验证问题集与人工复核样本开展效果评估和迭代。 | I32: 符合纳入标准（≥2条文字意见 或 ≥3位专家在任一维度给≤2分），纳入第二轮复评确认。 | K32: 2026-10-08
A33: P03 | B33: R1 | C33: 智能体业务流程改造项目：完成流程分析、智能体编排、权限边界和运行评估。 | D33: I-CVI=1.000；D1中位数=4.0，IQR=1.00，同意数=12/12；D2/D3/D4/D5中位数=4.0/3.0/3.0/4.0 | E33: D1内容相关性I-CVI=1.000、中位数=4.0，达到保留阈值（≥0.78）。 | F33: [E05] 限定工具数量和业务风险，控制项目难度。；另低分：[E02] D4=2；[E06] D4=2；[V04] D3=2 | G33: 修订进入R2 | H33: 完成流程分析、受限工具集下的智能体编排、权限边界与运行评估；限定工具数量与业务风险以控制项目难度。 | I33: 符合纳入标准（≥2条文字意见 或 ≥3位专家在任一维度给≤2分），纳入第二轮复评确认。 | K33: 2026-10-08
A34: P04 | B34: R1 | C34: 综合人工智能应用交付项目：按需求—开发—安全—部署—验收—运维全流程交付。 | D34: I-CVI=1.000；D1中位数=4.0，IQR=1.00，同意数=12/12；D2/D3/D4/D5中位数=4.0/3.5/3.0/4.0 | E34: D1内容相关性I-CVI=1.000、中位数=4.0，达到保留阈值（≥0.78）。 | F34: [E01] 建议分阶段验收，避免项目范围过大。；[V01] 建议拆成两个学期递进实施。；[V05] 项目边界需与企业导师提前确认。；[V06] 综合项目应允许使用托管服务替代自建平台。；另低分：[E01] D2=2；[E03] D4=2；[E05] D4=2；[V03] D4=2 | G34: 修订进入R2 | H34: 按需求—开发—安全—部署—验收—运维全流程分阶段交付与验收；边界与企业导师提前确认，允许以托管服务替代自建平台，可拆分为两学期递进实施。 | I34: 符合纳入标准（≥2条文字意见 或 ≥3位专家在任一维度给≤2分），纳入第二轮复评确认。 | K34: 2026-10-08
A35: E01 | B35: R1 | C35: 需求规格说明书：证明需求获取、边界确认和验收标准定义能力。 | D35: I-CVI=1.000；D1中位数=4.0，IQR=0.00，同意数=12/12；D2/D3/D4/D5中位数=4.0/4.0/4.0/4.0 | E35: D1内容相关性I-CVI=1.000、中位数=4.0，达到保留阈值（≥0.78）。 | F35: 无（未提出文字修改意见） | G35: 保留 | I35: 未达纳入第二轮阈值（文字意见<2条且低分专家<3人），且I-CVI≥0.78，保留原条目。 | K35: 2026-10-08
A36: E02 | B36: R1 | C36: 业务流程图与场景分析报告：证明流程理解、问题识别和适用性判断能力。 | D36: I-CVI=1.000；D1中位数=3.0，IQR=1.00，同意数=12/12；D2/D3/D4/D5中位数=4.0/3.0/3.5/4.0 | E36: D1内容相关性I-CVI=1.000、中位数=3.0，达到保留阈值（≥0.78）。 | F36: [V04] 报告应附原始访谈或观察证据。 | G36: 保留 | I36: 未达纳入第二轮阈值（文字意见<2条且低分专家<3人），且I-CVI≥0.78，保留原条目。 | K36: 2026-10-08
A37: E03 | B37: R1 | C37: 模型选型与技术方案报告：证明模型、成本、风险和部署约束的综合判断。 | D37: I-CVI=1.000；D1中位数=4.0，IQR=1.00，同意数=12/12；D2/D3/D4/D5中位数=4.0/3.0/4.0/4.0 | E37: D1内容相关性I-CVI=1.000、中位数=4.0，达到保留阈值（≥0.78）。 | F37: [V01] 技术方案报告可提供统一模板。 | G37: 保留 | I37: 未达纳入第二轮阈值（文字意见<2条且低分专家<3人），且I-CVI≥0.78，保留原条目。 | K37: 2026-10-08
A38: E04 | B38: R1 | C38: RAG/智能体运行与评测记录：证明实现过程、测试样例、指标和迭代依据。 | D38: I-CVI=1.000；D1中位数=4.0，IQR=0.00，同意数=12/12；D2/D3/D4/D5中位数=4.0/4.0/4.0/4.0 | E38: D1内容相关性I-CVI=1.000、中位数=4.0，达到保留阈值（≥0.78）。 | F38: [E01] 评测记录应包含失败样例与版本号。；[E04] 区分检索、生成和端到端评测结果。；[V04] 运行记录建议统一字段，便于复核。 | G38: 修订进入R2 | H38: 证明实现过程、测试样例、指标与迭代依据；记录统一字段，区分检索、生成和端到端评测，并包含失败样例与版本号。 | I38: 符合纳入标准（≥2条文字意见 或 ≥3位专家在任一维度给≤2分），纳入第二轮复评确认。 | K38: 2026-10-08
A39: E05 | B39: R1 | C39: 数据清单、授权与隐私处理记录：证明数据来源、用途、权限和保护措施可追溯。 | D39: I-CVI=1.000；D1中位数=4.0，IQR=0.00，同意数=12/12；D2/D3/D4/D5中位数=4.0/4.0/4.0/3.5 | E39: D1内容相关性I-CVI=1.000、中位数=4.0，达到保留阈值（≥0.78）。 | F39: [V03] 记录模板需体现最小化和保存期限。 | G39: 保留 | I39: 未达纳入第二轮阈值（文字意见<2条且低分专家<3人），且I-CVI≥0.78，保留原条目。 | K39: 2026-10-08
A40: E06 | B40: R1 | C40: 安全风险评估与测试报告：证明开展幻觉、注入、权限边界和异常场景测试。 | D40: I-CVI=1.000；D1中位数=3.0，IQR=1.00，同意数=12/12；D2/D3/D4/D5中位数=4.0/4.0/3.0/4.0 | E40: D1内容相关性I-CVI=1.000、中位数=3.0，达到保留阈值（≥0.78）。 | F40: [E03] 报告应列明风险等级、责任人与整改闭环。；另低分：[E04] D4=2；[E06] D4=2；[V04] D4=2 | G40: 修订进入R2 | H40: 报告须列明风险等级、责任人与整改闭环，并附幻觉、注入、权限边界和异常场景测试记录。 | I40: 符合纳入标准（≥2条文字意见 或 ≥3位专家在任一维度给≤2分），纳入第二轮复评确认。 | K40: 2026-10-08
...

Sheet 第二轮录入
A1: 专家编号 | B1: 专家组 | C1: 条目编号 | D1: 修订后条目 | E1: R1 I-CVI | F1: R1中位数 | G1: R1 IQR | H1: R2相关性1–4 | I1: 是否赞成修订 | J1: 意见
A2: E01 | B2: 企业专家 | C2: T01 | D2: 能够通过访谈、观察和资料分析，形成含验收标准与优先级的可测试业务需求，并参与企业需求评审。 | E2: 1 | F2: 4 | G2: 0 | H2: 4 | I2: 是
A3: E01 | B3: 企业专家 | C3: T03 | D3: 能够形成技术—业务方案，明确里程碑与变更控制机制，并参与范围、进度和风险协调。 | E3: 1 | F3: 3 | G3: 1 | H3: 4 | I3: 是 | J3: 里程碑与变更控制已吸收第一轮建议，表述可直接采用。
A4: E01 | B4: 企业专家 | C4: T06 | D4: 能够完成数据处理、索引、检索、生成和效果评估，并以基准问题集度量检索召回率、引用正确率与更新时效。 | E4: 1 | F4: 4 | G4: 0 | H4: 4 | I4: 是
A5: E01 | B5: 企业专家 | C5: T08 | D5: 能够根据场景集成多模态能力（以接口调用为主）；轻量化微调作为拓展／选学任务，不作为必达要求。 | E5: 1 | F5: 3 | G5: 1 | H5: 3 | I5: 是
A6: E01 | B6: 企业专家 | C6: T11 | D6: 能够建立事实性、稳定性、可追溯性和拒答能力测试，并按业务风险设定通过阈值与最低样本量。 | E6: 1 | F6: 4 | G6: 0 | H6: 4 | I6: 是
A7: E01 | B7: 企业专家 | C7: T12 | D7: 在授权范围内识别并测试恶意提示、间接注入和防护措施；测试须限定授权范围并保留记录。 | E7: 1 | F7: 3.5 | G7: 1 | H7: 4 | I7: 是
A8: E01 | B8: 企业专家 | C8: T13 | D8: 能够验证工具白名单、参数约束与异常处置，明确高风险工具调用须经人工确认；工具参数校验列为必测项。 | E8: 1 | F8: 4 | G8: 1 | H8: 4 | I8: 是
A9: E01 | B9: 企业专家 | C9: T15 | D9: 能够识别偏见、版权、责任边界及行业合规要求，覆盖生成内容标识与责任追溯，并通过案例辨析责任角色。 | E9: 1 | F9: 4 | G9: 0 | H9: 4 | I9: 是
A10: E01 | B10: 企业专家 | C10: T17 | D10: 能够完成镜像、配置、资源限额、服务发布、灰度发布与回滚；以单机容器为基础、集群部署为拓展，深度控制在高职可操作范围。 | E10: 0.917 | F10: 3 | G10: 1 | H10: 3 | I10: 是
A11: E01 | B11: 企业专家 | C11: T19 | D11: 能够监控模型质量与平台可用性两类指标（含质量、时延、成本、安全）并定位故障；配套预设故障与可观察指标。 | E11: 1 | F11: 3.5 | G11: 1 | H11: 4 | I11: 是
A12: E01 | B12: 企业专家 | C12: T20 | D12: 能够形成可维护文档，面向管理员与普通用户分层培训，并完成可由企业导师模拟签收的交接与知识转移。 | E12: 1 | F12: 3 | G12: 1 | H12: 4 | I12: 是
A13: E01 | B13: 企业专家 | C13: C05 | D13: 训练任务规划、工具调用、权限控制和人机协同；按“先单智能体、再多步骤流程”的梯度组织，降低编排复杂度。 | E13: 1 | F13: 3 | G13: 0.25 | H13: 4 | I13: 是
A14: E01 | B14: 企业专家 | C14: C06 | D14: 覆盖数据、模型、应用、智能体和业务治理；以风险评估贯穿其他模块，并与各项目共用统一检查清单。 | E14: 1 | F14: 4 | G14: 0 | H14: 4 | I14: 是
A15: E01 | B15: 企业专家 | C15: C07 | D15: 训练API、容器、服务编排、发布和回滚；采用轻量集群或托管平台降低门槛，并注明最低算力、网络与平台条件。 | E15: 1 | F15: 3.5 | G15: 1 | H15: 4 | I15: 是
... A19: E01 | B19: 企业专家 | C19: P03 | D19: 完成流程分析、受限工具集下的智能体编排、权限边界与运行评估；限定工具数量与业务风险以控制项目难度。 | E19: 1 | F19: 4 | G19: 1 | H19: 4 | I19: 是
A20: E01 | B20: 企业专家 | C20: P04 | D20: 按需求—开发—安全—部署—验收—运维全流程分阶段交付与验收；边界与企业导师提前确认，允许以托管服务替代自建平台，可拆分为两学期递进实施。 | E20: 1 | F20: 4 | G20: 1 | H20: 3 | I20: 是 | J20: 赞成分阶段验收，但“两学期”宜作为实施建议，不固定写入项目能力要求。
A21: E01 | B21: 企业专家 | C21: E04 | D21: 证明实现过程、测试样例、指标与迭代依据；记录统一字段，区分检索、生成和端到端评测，并包含失败样例与版本号。 | E21: 1 | F21: 4 | G21: 0 | H21: 4 | I21: 是
A22: E01 | B22: 企业专家 | C22: E06 | D22: 报告须列明风险等级、责任人与整改闭环，并附幻觉、注入、权限边界和异常场景测试记录。 | E22: 1 | F22: 3 | G22: 1 | H22: 4 | I22: 是
A23: E01 | B23: 企业专家 | C23: E08 | D23: （本条暂无文字修订建议；R2 仅就“未来三年重要性”与“高职可行性”的定位征询意见，修订文本待R2反馈后确定） | E23: 1 | F23: 3 | G23: 1 | H23: 3 | I23: 否 | J23: 建议保留为核心证据；未来三年重要性高，高职阶段可采用仿真监控与事件演练。
A24: E01 | B24: 企业专家 | C24: E09 | D24: 验收材料需包含签字角色与未决项，并将用户反馈纳入验收证据。 | E24: 1 | F24: 4 | G24: 1 | H24: 4 | I24: 是
A25: E02 | B25: 企业专家 | C25: T01 | D25: 能够通过访谈、观察和资料分析，形成含验收标准与优先级的可测试业务需求，并参与企业需求评审。 | E25: 1 | F25: 4 | G25: 0 | H25: 4 | I25: 是
A26: E02 | B26: 企业专家 | C26: T03 | D26: 能够形成技术—业务方案，明确里程碑与变更控制机制，并参与范围、进度和风险协调。 | E26: 1 | F26: 3 | G26: 1 | H26: 4 | I26: 是
A27: E02 | B27: 企业专家 | C27: T06 | D27: 能够完成数据处理、索引、检索、生成和效果评估，并以基准问题集度量检索召回率、引用正确率与更新时效。 | E27: 1 | F27: 4 | G27: 0 | H27: 4 | I27: 是
A28: E02 | B28: 企业专家 | C28: T08 | D28: 能够根据场景集成多模态能力（以接口调用为主）；轻量化微调作为拓展／选学任务，不作为必达要求。 | E28: 1 | F28: 3 | G28: 1 | H28: 3 | I28: 是
A29: E02 | B29: 企业专家 | C29: T11 | D29: 能够建立事实性、稳定性、可追溯性和拒答能力测试，并按业务风险设定通过阈值与最低样本量。 | E29: 1 | F29: 4 | G29: 0 | H29: 4 | I29: 是
A30: E02 | B30: 企业专家 | C30: T12 | D30: 在授权范围内识别并测试恶意提示、间接注入和防护措施；测试须限定授权范围并保留记录。 | E30: 1 | F30: 3.5 | G30: 1 | H30: 4 | I30: 是
A31: E02 | B31: 企业专家 | C31: T13 | D31: 能够验证工具白名单、参数约束与异常处置，明确高风险工具调用须经人工确认；工具参数校验列为必测项。 | E31: 1 | F31: 4 | G31: 1 | H31: 4 | I31: 是
A32: E02 | B32: 企业专家 | C32: T15 | D32: 能够识别偏见、版权、责任边界及行业合规要求，覆盖生成内容标识与责任追溯，并通过案例辨析责任角色。 | E32: 1 | F32: 4 | G32: 0 | H32: 4 | I32: 是
A33: E02 | B33: 企业专家 | C33: T17 | D33: 能够完成镜像、配置、资源限额、服务发布、灰度发布与回滚；以单机容器为基础、集群部署为拓展，深度控制在高职可操作范围。 | E33: 0.917 | F33: 3 | G33: 1 | H33: 4 | I33: 是 | J33: 分层设置合理；灰度发布建议以演示或托管平台操作为主。
A34: E02 | B34: 企业专家 | C34: T19 | D34: 能够监控模型质量与平台可用性两类指标（含质量、时延、成本、安全）并定位故障；配套预设故障与可观察指标。 | E34: 1 | F34: 3.5 | G34: 1 | H34: 4 | I34: 是
A35: E02 | B35: 企业专家 | C35: T20 | D35: 能够形成可维护文档，面向管理员与普通用户分层培训，并完成可由企业导师模拟签收的交接与知识转移。 | E35: 1 | F35: 3 | G35: 1 | H35: 4 | I35: 是
A36: E02 | B36: 企业专家 | C36: C05 | D36: 训练任务规划、工具调用、权限控制和人机协同；按“先单智能体、再多步骤流程”的梯度组织，降低编排复杂度。 | E36: 1 | F36: 3 | G36: 0.25 | H36: 4 | I36: 是
A37: E02 | B37: 企业专家 | C37: C06 | D37: 覆盖数据、模型、应用、智能体和业务治理；以风险评估贯穿其他模块，并与各项目共用统一检查清单。 | E37: 1 | F37: 4 | G37: 0 | H37: 3 | I37: 是
A38: E02 | B38: 企业专家 | C38: C07 | D38: 训练API、容器、服务编排、发布和回滚；采用轻量集群或托管平台降低门槛，并注明最低算力、网络与平台条件。 | E38: 1 | F38: 3.5 | G38: 1 | H38: 4 | I38: 是 | J38: 认可轻量集群或托管平台路径，同时应保留资源配额与回滚要求。
A39: E02 | B39: 企业专家 | C39: C08 | D39: 训练日志、监控、质量评估、成本预算与资源回收、告警阈值设定和事件响应。 | E39: 1 | F39: 3 | G39: 1 | H39: 4 | I39: 是
A40: E02 | B40: 企业专家 | C40: C09 | D40: 训练项目协同、测试验收、变更记录与遗留问题清单、文档、培训和交接，并设置企业评审节点与沟通记录。 | E40: 1 | F40: 4 | G40: 0.25 | H40: 4 | I40: 是
A41: E02 | B41: 企业专家 | C41: P02 | D41: 完成授权语料治理（企业脱敏提供或共同构造）、检索生成，并以可验证问题集与人工复核样本开展效果评估和迭代。 | E41: 1 | F41: 4 | G41: 0 | H41: 4 | I41: 是
A42: E02 | B42: 企业专家 | C42: P03 | D42: 完成流程分析、受限工具集下的智能体编排、权限边界与运行评估；限定工具数量与业务风险以控制项目难度。 | E42: 1 | F42: 4 | G42: 1 | H42: 4 | I42: 是
A43: E02 | B43: 企业专家 | C43: P04 | D43: 按需求—开发—安全—部署—验收—运维全流程分阶段交付与验收；边界与企业导师提前确认，允许以托管服务替代自建平台，可拆分为两学期递进实施。 | E43: 1 | F43: 4 | G43: 1 | H43: 3 | I43: 是
...

Sheet 实施日志
A1: 日期 | B1: 阶段 | C1: 事件/偏离 | D1: 原因 | E1: 处理 | F1: 影响评估 | G1: 记录人 | H1: 复核人
A2: 2026-10-08 | B2: 伦理审查 | C2: 已通过所在单位伦理审查/备案，备案编号 SDLL2026001 | D2: 正式招募前的必经程序 | E2: 已将备案编号回填至研究材料包 A6 研究方案、B1 邀请函及 H 质量检查清单 | F2: 无偏离；可开始正式招募与第一轮数据收集
A3: 2026-10-08 | B3: 第一轮 | C3: 完成12份R1问卷回收与录入，第一轮统计完成；R2精简纳入23条 | D3: 按方案实施 | E3: 录入「第一轮录入」「前瞻判断」并运行分析脚本；在「条目修订日志」记录42条决策 | F3: 无偏离；R1数据完整，仅V04-C08.D5单格留空
A4: 2026-10-09 | B4: 第二轮 | C4: 完成12份R2问卷回收与录入；第二轮统计完成：22条修订获采纳、E08维持原文 | D4: 按方案实施 | E4: 录入「第二轮录入」276行；重跑分析脚本；在「条目修订日志」追加23条R2轮次决策 | F4: 无偏离；R2评分完整（0缺失/0越界）；12份均附“其他意见”

Sheet 论文结果模板
A1: 专家验证结果摘录模板（仅在真实分析后填写）
A2: 指标 | B2: 真实结果
A3: R1完成数 | B3: [ ] / 12
A4: R2完成数 | B4: [ ]
A5: 保留/修订/删除数 | B5: [ ] / [ ] / [ ]
A6: S-CVI/Ave | B6: [ ]
A7: 企业—教师主要分歧 | B7: [ ]
A8: 政策例外保留条目 | B8: [ ]
A9: 最终框架规模 | B9: 任务[ ]；课程[ ]；项目[ ]；评价证据[ ]
A10: 报告限制 | B10: 目的抽样、每组n=6、探索性组间比较、不可推断全国代表性
